Workbook

Sheet Summary All Corps
A1: Dates | B1: 1928 | C1: 1929 | D1: 1930 | E1: 1931 | F1: 1932 | G1: 1933 | H1: 1934 | I1: 1935 | J1: 1936 | K1: 1937 | L1: 1938 | M1: 1939 | N1: 1940 | O1: 1941 | P1: 1942 | Q1: 1943 | R1: 1944 | S1: 1945 | T1: 1946 | U1: 1947 | V1: 1948 | W1: 1949 | X1: 1950 | Y1: 1951 | Z1: 1952 | AA1: 1953 | AB1: 1954 | AC1: 1955 | AD1: 1956 | AE1: 1957 | AF1: 1958 | AG1: 1959 | AH1: 1960 | AI1: 1961 | AJ1: 1962 | AK1: 1963 | AL1: 1964 | AM1: 1965 | AN1: 1966 | AO1: 1967 | AP1: 1968 | AQ1: 1969 | AR1: 1970 | AS1: 1971 | AT1: 1972 | AU1: 1973 | AV1: 1974 | AW1: 1975 | AX1: 1976 | AY1: 1977 | AZ1: 1978 | BA1: 1979 | BB1: 1980 | BC1: 1981 | BD1: 1982 | BE1: 1983 | BF1: 1984 | BG1: 1985 | BH1: 1986 | BI1: 1987 | BJ1: 1988 | BK1: 1989 | BL1: 1990 | BM1: 1991 | BN1: 1992 | BO1: 1993 | BP1: 1994 | BQ1: 1995 | BR1: 1996 | BS1: 1997 | BT1: 1998 | BU1: 1999 | BV1: 2000 | BW1: 2001 | BX1: 2002 | BY1: 2003 | BZ1: 2004 | CA1: 2005 | CB1: 2006 | CC1: 2007 | CD1: 2008 | CE1: 2009 | CF1: 2010 | CG1: 2011 | CH1: 2012 | CI1: 2013 | CJ1: 2014 | CK1: 2015 | CL1: 2016 | CM1: 2017 | CN1: 2018 | CO1: 2019 | CP1: 2020 | CQ1: 2021 | CR1: 2022 | CS1: 2023 | CT1: 2024 | CU1: 2025
A2: GVA | B2: NaN | C2: ='NIPA 1.14'!C8 -> 54806 | D2: ='NIPA 1.14'!D8 -> 48178 | E2: ='NIPA 1.14'!E8 -> 37846 | F2: ='NIPA 1.14'!F8 -> 27861 | G2: ='NIPA 1.14'!G8 -> 26876 | H2: ='NIPA 1.14'!H8 -> 33500 | I2: ='NIPA 1.14'!I8 -> 37147 | J2: ='NIPA 1.14'!J8 -> 42724 | ... CT2: ='NIPA 1.14'!CT8 -> 16961079
A3: GFC | B3: NaN | C3: ='NIPA 1.14'!C9 -> 5228 | D3: ='NIPA 1.14'!D9 -> 5080 | E3: ='NIPA 1.14'!E9 -> 4752 | F3: ='NIPA 1.14'!F9 -> 4240 | G3: ='NIPA 1.14'!G9 -> 4008 | H3: ='NIPA 1.14'!H9 -> 4104 | I3: ='NIPA 1.14'!I9 -> 4184 | J3: ='NIPA 1.14'!J9 -> 4248 | ... CT3: ='NIPA 1.14'!CT9 -> 2583318
A4: Employee Compensation | B4: NaN | C4: ='NIPA 1.14'!C11 -> 34242 | D4: ='NIPA 1.14'!D11 -> 30808 | E4: ='NIPA 1.14'!E11 -> 25369 | F4: ='NIPA 1.14'!F11 -> 19013 | G4: ='NIPA 1.14'!G11 -> 18002 | H4: ='NIPA 1.14'!H11 -> 21045 | I4: ='NIPA 1.14'!I11 -> 23056 | J4: ='NIPA 1.14'!J11 -> 26274 | ... CT4: ='NIPA 1.14'!CT11 -> 9443321
A5: Indirect Business Taxes | B5: NaN | C5: ='NIPA 1.14'!C14 -> 2999 | D5: ='NIPA 1.14'!D14 -> 3037 | E5: ='NIPA 1.14'!E14 -> 2842 | F5: ='NIPA 1.14'!F14 -> 2942 | G5: ='NIPA 1.14'!G14 -> 3467 | H5: ='NIPA 1.14'!H14 -> 4090 | I5: ='NIPA 1.14'!I14 -> 4155 | J5: ='NIPA 1.14'!J14 -> 4364 | ... CT5: ='NIPA 1.14'!CT14 -> 1250767
A6: Net Operating Surplus | B6: NaN | C6: ='NIPA 1.14'!C15 -> 12337 | D6: ='NIPA 1.14'!D15 -> 9253 | E6: ='NIPA 1.14'!E15 -> 4883 | F6: ='NIPA 1.14'!F15 -> 1666 | G6: ='NIPA 1.14'!G15 -> 1399 | H6: ='NIPA 1.14'!H15 -> 4261 | I6: ='NIPA 1.14'!I15 -> 5752 | J6: ='NIPA 1.14'!J15 -> 7838 | ... CT6: ='NIPA 1.14'!CT15 -> 3683673
A7: Business Transfers | B7: NaN | C7: ='NIPA 1.14'!C17 -> 355 | D7: ='NIPA 1.14'!D17 -> 354 | E7: ='NIPA 1.14'!E17 -> 406 | F7: ='NIPA 1.14'!F17 -> 425 | G7: ='NIPA 1.14'!G17 -> 404 | H7: ='NIPA 1.14'!H17 -> 390 | I7: ='NIPA 1.14'!I17 -> 368 | J7: ='NIPA 1.14'!J17 -> 353 | ... CT7: ='NIPA 1.14'!CT17 -> 251287
A8: Taxes on Corporate Income | B8: NaN | C8: ='NIPA 1.14'!C19 -> 1365 | D8: ='NIPA 1.14'!D19 -> 842 | E8: ='NIPA 1.14'!E19 -> 498 | F8: ='NIPA 1.14'!F19 -> 383 | G8: ='NIPA 1.14'!G19 -> 521 | H8: ='NIPA 1.14'!H19 -> 744 | I8: ='NIPA 1.14'!I19 -> 951 | J8: ='NIPA 1.14'!J19 -> 1409 | ... CT8: ='NIPA 1.14'!CT19 -> 680341
A9: Investment | B9: NaN | C9: ='FA 6.7'!AE10 -> 8158 | D9: ='FA 6.7'!AF10 -> 6759 | E9: ='FA 6.7'!AG10 -> 4381 | F9: ='FA 6.7'!AH10 -> 2687 | G9: ='FA 6.7'!AI10 -> 2487 | H9: ='FA 6.7'!AJ10 -> 3085 | I9: ='FA 6.7'!AK10 -> 3574 | J9: ='FA 6.7'!AL10 -> 4598 | ... S9: ='FA 6.7'!AU10 -> 9152 | T9: ='CapitalDataL4+'!I20 -> 13908 | U9: ='CapitalDataL4+'!J20 -> 17936 | V9: ='CapitalDataL4+'!K20 -> 19821 | W9: ='CapitalDataL4+'!L20 -> 18033 | X9: ='CapitalDataL4+'!M20 -> 19819 | Y9: ='CapitalDataL4+'!N20 -> 23784 | Z9: ='CapitalDataL4+'!O20 -> 25310 | AA9: ='CapitalDataL4+'!P20 -> 28106 | ... CT9: ='CapitalDataL4+'!CI20 -> 3308281
A10: Free Cash Flow | B10: NaN | C10: =C2-C4-C5-C7-C8-C9 -> 7687 | D10: =D2-D4-D5-D7-D8-D9 -> 6378 | E10: =E2-E4-E5-E7-E8-E9 -> 4350 | F10: =F2-F4-F5-F7-F8-F9 -> 2411 | G10: =G2-G4-G5-G7-G8-G9 -> 1995 | H10: =H2-H4-H5-H7-H8-H9 -> 4146 | I10: =I2-I4-I5-I7-I8-I9 -> 5043 | J10: =J2-J4-J5-J7-J8-J9 -> 5726 | ... CT10: =CT2-CT4-CT5-CT7-CT8-CT9 -> 2027082
A11: Reproduction Value of Capital | B11: ='FA 6.1'!F10 -> 106916 | C11: ='FA 6.1'!G10 -> 106016 | D11: ='FA 6.1'!H10 -> 100962 | E11: ='FA 6.1'!I10 -> 90747 | F11: ='FA 6.1'!J10 -> 84747 | G11: ='FA 6.1'!K10 -> 85527 | H11: ='FA 6.1'!L10 -> 86754 | I11: ='FA 6.1'!M10 -> 86308 | ... R11: ='FA 6.1'!V10 -> 126747 | S11: ='CapitalDataL4+'!H19 -> 139208 | T11: ='CapitalDataL4+'!I19 -> 168356 | U11: ='CapitalDataL4+'!J19 -> 200698 | V11: ='CapitalDataL4+'!K19 -> 219642 | W11: ='CapitalDataL4+'!L19 -> 223678 | X11: ='CapitalDataL4+'!M19 -> 250857 | Y11: ='CapitalDataL4+'!N19 -> 272459 | Z11: ='CapitalDataL4+'!O19 -> 288532 | ... CT11: ='CapitalDataL4+'!CI19 -> 27603501
A12: Enterprise Value | B12: ='SOI 1945'!E16 -> 173056.56 | C12: ='SOI 1945'!F16 -> 164239.53 | D12: ='SOI 1945'!G16 -> 132259.85 | E12: ='SOI 1945'!H16 -> 85383.618 | F12: ='SOI 1945'!I16 -> 73446.334 | G12: ='SOI 1945'!J16 -> 96459.518 | H12: ='SOI 1945'!K16 -> 84167.436 | I12: ='SOI 1945'!L16 -> 111217.37 | ... R12: ='SOI 1945'!U16 -> 140989.25 | S12: ='B1'!G16+'B1'!G17 -> 152328 | T12: ='B1'!H16+'B1'!H17 -> 158831 | U12: ='B1'!I16+'B1'!I17 -> 161921 | V12: ='B1'!J16+'B1'!J17 -> 165216 | W12: ='B1'!K16+'B1'!K17 -> 170947 | X12: ='B1'!L16+'B1'!L17 -> 199319 | Y12: ='B1'!M16+'B1'!M17 -> 246419 | Z12: ='B1'!N16+'B1'!N17 -> 240284 | ... CT12: ='B1'!CH16+'B1'!CH17 -> 81137445
A13: Direct Capital Revaluations | B13: NaN | C13: NaN | D13: NaN | E13: NaN | F13: NaN | G13: NaN | H13: NaN | I13: NaN | J13: NaN | K13: NaN | L13: NaN | M13: NaN | N13: NaN | O13: NaN | P13: NaN | Q13: NaN | R13: NaN | S13: NaN | T13: ='CapitalDataL4+'!I22 -> 23297 | U13: ='CapitalDataL4+'!J22 -> 24275 | V13: ='CapitalDataL4+'!K22 -> 10695 | W13: ='CapitalDataL4+'!L22 -> -1493 | X13: ='CapitalDataL4+'!M22 -> 20749 | Y13: ='CapitalDataL4+'!N22 -> 13071 | Z13: ='CapitalDataL4+'!O22 -> 7006 | AA13: ='CapitalDataL4+'!P22 -> 4234 | ... CT13: ='CapitalDataL4+'!CI22 -> 192800
A14: Top Corp Tax Rate | B14: ='Top Corporate Tax Rate'!B5 -> 0.12 | C14: ='Top Corporate Tax Rate'!C5 -> 0.11 | D14: ='Top Corporate Tax Rate'!D5 -> 0.12 | E14: ='Top Corporate Tax Rate'!E5 -> 0.12 | F14: ='Top Corporate Tax Rate'!F5 -> 0.1375 | G14: ='Top Corporate Tax Rate'!G5 -> 0.1375 | H14: ='Top Corporate Tax Rate'!H5 -> 0.1375 | I14: ='Top Corporate Tax Rate'!I5 -> 0.1375 | ... CT14: ='Top Corporate Tax Rate'!CT5 -> 0.21
A15: Gravelle EMTR | B15: ='Gravelle Rates'!B5 -> NaN | C15: ='Gravelle Rates'!C5 -> NaN | D15: ='Gravelle Rates'!D5 -> NaN | E15: ='Gravelle Rates'!E5 -> NaN | F15: ='Gravelle Rates'!F5 -> NaN | G15: ='Gravelle Rates'!G5 -> NaN | H15: ='Gravelle Rates'!H5 -> NaN | I15: ='Gravelle Rates'!I5 -> NaN | ... CT15: ='Gravelle Rates'!CT5 -> NaN
A16: PCE Deflator | B16: NaN | C16: ='PCE Deflator'!C8 -> 8.787 | D16: ='PCE Deflator'!D8 -> 8.415 | E16: ='PCE Deflator'!E8 -> 7.514 | F16: ='PCE Deflator'!F8 -> 6.627 | G16: ='PCE Deflator'!G8 -> 6.391 | H16: ='PCE Deflator'!H8 -> 6.681 | I16: ='PCE Deflator'!I8 -> 6.846 | J16: ='PCE Deflator'!J8 -> 6.909 | ... CT16: ='PCE Deflator'!CT8 -> 123.666
A17: CRSP Rwd | B17: ='CRSP Data'!D2 -> 0.3913965 | C17: ='CRSP Data'!E2 -> -0.1509553 | D17: ='CRSP Data'!F2 -> -0.2890045 | E17: ='CRSP Data'!G2 -> -0.4438795 | F17: ='CRSP Data'!H2 -> -0.07944798 | G17: ='CRSP Data'!I2 -> 0.5741313 | H17: ='CRSP Data'!J2 -> 0.03184588 | I17: ='CRSP Data'!K2 -> 0.454487 | ... CT17: ='CRSP Data'!CV2 -> 0.228557
A18: One Year Nominal Rate | B18: NaN | C18: NaN | D18: NaN | E18: NaN | F18: NaN | G18: NaN | H18: NaN | I18: NaN | J18: NaN | K18: NaN | L18: NaN | M18: NaN | N18: NaN | O18: NaN | P18: NaN | Q18: NaN | R18: NaN | S18: NaN | T18: NaN | U18: NaN | V18: NaN | W18: NaN | X18: NaN | Y18: NaN | Z18: NaN | AA18: NaN | AB18: ='Interest Rates'!B33 -> 1.21 | AC18: ='Interest Rates'!C33 -> 2.73 | AD18: ='Interest Rates'!D33 -> 3.68 | AE18: ='Interest Rates'!E33 -> 3.18 | AF18: ='Interest Rates'!F33 -> 3.29 | AG18: ='Interest Rates'!G33 -> 5.14 | AH18: ='Interest Rates'!H33 -> 2.86 | AI18: ='Interest Rates'!I33 -> 3.18 | ... CT18: ='Interest Rates'!BT33 -> 4.23
A19: Ten Year Nominal Rate | B19: ='Interest Rates'!E10 -> 3.45 | C19: ='Interest Rates'!F10 -> 3.36 | D19: ='Interest Rates'!G10 -> 3.22 | E19: ='Interest Rates'!H10 -> 3.93 | F19: ='Interest Rates'!I10 -> 3.35 | G19: ='Interest Rates'!J10 -> 3.53 | H19: ='Interest Rates'!K10 -> 3.01 | I19: ='Interest Rates'!L10 -> 2.84 | ... AA19: ='Interest Rates'!AD10 -> 2.79 | AB19: ='Interest Rates'!B21 -> 2.51 | AC19: ='Interest Rates'!C21 -> 2.96 | AD19: ='Interest Rates'!D21 -> 3.59 | AE19: ='Interest Rates'!E21 -> 3.21 | AF19: ='Interest Rates'!F21 -> 3.86 | AG19: ='Interest Rates'!G21 -> 4.69 | AH19: ='Interest Rates'!H21 -> 3.84 | AI19: ='Interest Rates'!I21 -> 4.06 | ... CT19: ='Interest Rates'!BT21 -> 4.39
A20: Cleveland Ten Year Real Rate | B20: NaN | C20: NaN | D20: NaN | E20: NaN | F20: NaN | G20: NaN | H20: NaN | I20: NaN | J20: NaN | K20: NaN | L20: NaN | M20: NaN | N20: NaN | O20: NaN | P20: NaN | Q20: NaN | R20: NaN | S20: NaN | T20: NaN | U20: NaN | V20: NaN | W20: NaN | X20: NaN | Y20: NaN | Z20: NaN | AA20: NaN | AB20: NaN | AC20: NaN | AD20: NaN | AE20: NaN | AF20: NaN | AG20: NaN | AH20: NaN | AI20: NaN | AJ20: NaN | AK20: NaN | AL20: NaN | AM20: NaN | AN20: NaN | AO20: NaN | AP20: NaN | AQ20: NaN | AR20: NaN | AS20: NaN | AT20: NaN | AU20: NaN | AV20: NaN | AW20: NaN | AX20: NaN | AY20: NaN | AZ20: NaN | BA20: NaN | BB20: NaN | BC20: NaN | BD20: ='Interest Rates'!B46 -> 5.8817314 | BE20: ='Interest Rates'!C46 -> 6.1484245 | BF20: ='Interest Rates'!D46 -> 6.0756251 | BG20: ='Interest Rates'!E46 -> 5.0807695 | BH20: ='Interest Rates'!F46 -> 3.5437344 | BI20: ='Interest Rates'!G46 -> 4.5792755 | BJ20: ='Interest Rates'!H46 -> 4.6179387 | BK20: ='Interest Rates'!I46 -> 4.0296658 | ... CT20: ='Interest Rates'!AR46 -> 1.8243688
A21: One Year Inflation Expectations | B21: NaN | C21: NaN | D21: NaN | E21: NaN | F21: NaN | G21: NaN | H21: NaN | I21: NaN | J21: NaN | K21: NaN | L21: NaN | M21: NaN | N21: NaN | O21: NaN | P21: NaN | Q21: NaN | R21: NaN | S21: NaN | T21: NaN | U21: NaN | V21: NaN | W21: NaN | X21: NaN | Y21: NaN | Z21: NaN | AA21: NaN | AB21: NaN | AC21: NaN | AD21: NaN | AE21: NaN | AF21: NaN | AG21: NaN | AH21: NaN | AI21: NaN | AJ21: NaN | AK21: NaN | AL21: NaN | AM21: NaN | AN21: NaN | AO21: NaN | AP21: NaN | AQ21: NaN | AR21: ='Inflation Forecasts'!B6 -> 3.5414 | AS21: ='Inflation Forecasts'!C6 -> 3.4194 | AT21: ='Inflation Forecasts'!D6 -> 3.6999 | AU21: ='Inflation Forecasts'!E6 -> 5.3651 | AV21: ='Inflation Forecasts'!F6 -> 7.6814 | AW21: ='Inflation Forecasts'!G6 -> 6.2087 | AX21: ='Inflation Forecasts'!H6 -> 5.729 | AY21: ='Inflation Forecasts'!I6 -> 5.9557 | ... BQ21: ='Inflation Forecasts'!AA6 -> 2.3505 | BR21: NaN | BS21: NaN | BT21: NaN | BU21: NaN | BV21: NaN | BW21: NaN | BX21: NaN | BY21: NaN | BZ21: NaN | CA21: NaN | CB21: NaN | CC21: NaN | CD21: NaN | CE21: NaN | CF21: NaN | CG21: NaN | CH21: NaN | CI21: NaN | CJ21: NaN | CK21: NaN | CL21: NaN | CM21: NaN | CN21: NaN | CO21: NaN | CP21: NaN | CQ21: NaN | CR21: NaN | CS21: NaN | CT21: NaN
A22: Ten Year Inflation Expectations | B22: NaN | C22: NaN | D22: NaN | E22: NaN | F22: NaN | G22: NaN | H22: NaN | I22: NaN | J22: NaN | K22: NaN | L22: NaN | M22: NaN | N22: NaN | O22: NaN | P22: NaN | Q22: NaN | R22: NaN | S22: NaN | T22: NaN | U22: NaN | V22: NaN | W22: NaN | X22: NaN | Y22: NaN | Z22: NaN | AA22: NaN | AB22: NaN | AC22: NaN | AD22: NaN | AE22: NaN | AF22: NaN | AG22: NaN | AH22: NaN | AI22: NaN | AJ22: NaN | AK22: NaN | AL22: NaN | AM22: NaN | AN22: NaN | AO22: NaN | AP22: NaN | AQ22: NaN | AR22: NaN | AS22: NaN | AT22: NaN | AU22: NaN | AV22: NaN | AW22: NaN | AX22: NaN | AY22: NaN | AZ22: NaN | BA22: ='Inflation Forecasts'!K7 -> 6.9 | BB22: ='Inflation Forecasts'!L7 -> 8.25 | BC22: ='Inflation Forecasts'!M7 -> 7.05 | BD22: ='Inflation Forecasts'!N7 -> 5.65 | BE22: ='Inflation Forecasts'!O7 -> 5.2 | BF22: ='Inflation Forecasts'!P7 -> 5.2 | BG22: ='Inflation Forecasts'!Q7 -> 4.55 | BH22: ='Inflation Forecasts'!R7 -> 4 | ... BQ22: ='Inflation Forecasts'!AA7 -> 3 | BR22: NaN | BS22: NaN | BT22: NaN | BU22: NaN | BV22: NaN | BW22: NaN | BX22: NaN | BY22: NaN | BZ22: NaN | CA22: NaN | CB22: NaN | CC22: NaN | CD22: NaN | CE22: NaN | CF22: NaN | CG22: NaN | CH22: NaN | CI22: NaN | CJ22: NaN | CK22: NaN | CL22: NaN | CM22: NaN | CN22: NaN | CO22: NaN | CP22: NaN | CQ22: NaN | CR22: NaN | CS22: NaN | CT22: NaN
A23: Ten Year Real Rate Extended | B23: NaN | C23: NaN | D23: NaN | E23: NaN | F23: NaN | G23: NaN | H23: NaN | I23: NaN | J23: NaN | K23: NaN | L23: NaN | M23: NaN | N23: NaN | O23: NaN | P23: NaN | Q23: NaN | R23: NaN | S23: NaN | T23: NaN | U23: NaN | V23: NaN | W23: NaN | X23: NaN | Y23: NaN | Z23: NaN | AA23: NaN | AB23: NaN | AC23: NaN | AD23: NaN | AE23: NaN | AF23: NaN | AG23: NaN | AH23: NaN | AI23: NaN | AJ23: NaN | AK23: NaN | AL23: NaN | AM23: NaN | AN23: NaN | AO23: NaN | AP23: NaN | AQ23: NaN | AR23: =AR19-AR21 -> 2.8486 | AS23: =AS19-AS21 -> 2.5106 | AT23: =AT19-AT21 -> 2.6601 | AU23: =AU19-AU21 -> 1.3749 | AV23: =AV19-AV21 -> -0.2514 | AW23: =AW19-AW21 -> 1.7913 | AX23: =AX19-AX21 -> 1.141 | AY23: =AY19-AY21 -> 1.7343 | AZ23: =AZ19-AZ21 -> 1.9173 | BA23: =BA19-BA22 -> 3.49 | BB23: =BB19-BB22 -> 4.59 | BC23: =BC19-BC22 -> 6.67 | BD23: =BD19-BD22 -> 4.89 | BE23: =BE19-BE22 -> 6.63 | BF23: =BF19-BF22 -> 6.3 | BG23: =BG19-BG22 -> 4.71 | BH23: =BH19-BH22 -> 3.11 | ... BQ23: =BQ19-BQ22 -> 2.71 | BR23: NaN | BS23: NaN | BT23: NaN | BU23: NaN | BV23: NaN | BW23: NaN | BX23: NaN | BY23: NaN | BZ23: NaN | CA23: NaN | CB23: NaN | CC23: NaN | CD23: NaN | CE23: NaN | CF23: NaN | CG23: NaN | CH23: NaN | CI23: NaN | CJ23: NaN | CK23: NaN | CL23: NaN | CM23: NaN | CN23: NaN | CO23: NaN | CP23: NaN | CQ23: NaN | CR23: NaN | CS23: NaN | CT23: NaN
A24: rstar LW | B24: NaN | C24: NaN | D24: NaN | E24: NaN | F24: NaN | G24: NaN | H24: NaN | I24: NaN | J24: NaN | K24: NaN | L24: NaN | M24: NaN | N24: NaN | O24: NaN | P24: NaN | Q24: NaN | R24: NaN | S24: NaN | T24: NaN | U24: NaN | V24: NaN | W24: NaN | X24: NaN | Y24: NaN | Z24: NaN | AA24: NaN | AB24: NaN | AC24: NaN | AD24: NaN | AE24: NaN | AF24: NaN | AG24: NaN | AH24: NaN | AI24: ='rstar estimates'!B17 -> 4.3229116 | AJ24: ='rstar estimates'!C17 -> 4.2908936 | AK24: ='rstar estimates'!D17 -> 4.310704 | AL24: ='rstar estimates'!E17 -> 4.313279 | AM24: ='rstar estimates'!F17 -> 4.2307805 | AN24: ='rstar estimates'!G17 -> 4.0618104 | AO24: ='rstar estimates'!H17 -> 3.9081264 | AP24: ='rstar estimates'!I17 -> 3.6876784 | ... CT24: ='rstar estimates'!BM17 -> 1.5445383
A25: rstar HLW | B25: NaN | C25: NaN | D25: NaN | E25: NaN | F25: NaN | G25: NaN | H25: NaN | I25: NaN | J25: NaN | K25: NaN | L25: NaN | M25: NaN | N25: NaN | O25: NaN | P25: NaN | Q25: NaN | R25: NaN | S25: NaN | T25: NaN | U25: NaN | V25: NaN | W25: NaN | X25: NaN | Y25: NaN | Z25: NaN | AA25: NaN | AB25: NaN | AC25: NaN | AD25: NaN | AE25: NaN | AF25: NaN | AG25: NaN | AH25: NaN | AI25: ='rstar estimates'!B21 -> 5.5022072 | AJ25: ='rstar estimates'!C21 -> 4.223001 | AK25: ='rstar estimates'!D21 -> 4.2365271 | AL25: ='rstar estimates'!E21 -> 4.3053377 | AM25: ='rstar estimates'!F21 -> 5.1099439 | AN25: ='rstar estimates'!G21 -> 5.0467335 | AO25: ='rstar estimates'!H21 -> 4.7519318 | AP25: ='rstar estimates'!I21 -> 4.7482959 | ... CT25: ='rstar estimates'!BM21 -> 0.91973286
A26: rstar DelNegro | B26: ='rstar estimates'!B29 -> 1.7683695 | C26: ='rstar estimates'!C29 -> 1.7253975 | D26: ='rstar estimates'!D29 -> 1.6538956 | E26: ='rstar estimates'!E29 -> 1.6858968 | F26: ='rstar estimates'!F29 -> 1.668671 | G26: ='rstar estimates'!G29 -> 1.6165772 | H26: ='rstar estimates'!H29 -> 1.5381355 | I26: ='rstar estimates'!I29 -> 1.4950429 | ... CT26: ='rstar estimates'!CT29 -> NaN
A27: SP Earnings Yield | B27: 0.054078396 | C27: 0.070465325 | D27: 0.078361586 | E27: 0.087915662 | F27: 0.070476148 | G27: 0.043638643 | H27: 0.050496877 | I27: 0.057240047 | J27: 0.052391368 | K27: 0.10429037 | L27: 0.061875003 | M27: 0.06291684 | N27: 0.09821052 | O27: 0.13404121 | P27: 0.10973215 | Q27: 0.092395006 | R27: 0.07113386 | S27: 0.056911023 | T27: 0.066662007 | U27: 0.098943277 | V27: 0.12696587 | W27: 0.14203692 | X27: 0.1352645 | Y27: 0.11600427 | Z27: 0.091855623 | AA27: 0.10080819 | AB27: 0.074530637 | AC27: 0.071447211 | AD27: 0.077809928 | AE27: 0.085695527 | AF27: 0.056177462 | AG27: 0.056186575 | AH27: 0.058679526 | AI27: 0.043321962 | AJ27: 0.055663702 | AK27: 0.052412501 | AL27: 0.051971369 | AM27: 0.05356292 | AN27: 0.067730958 | AO27: 0.057284553 | AP27: 0.053387816 | AQ27: 0.065789246 | AR27: 0.062249744 | AS27: 0.054953032 | AT27: 0.05210128 | AU27: 0.08032695 | AV27: 0.1367668 | AW27: 0.094396568 | AX27: 0.089612378 | AY27: 0.11402825 | AZ27: 0.12298138 | BA27: 0.137001 | BB27: 0.11722883 | BC27: 0.12537116 | BD27: 0.10183552 | BE27: 0.080208812 | BF27: 0.098231724 | BG27: 0.076650231 | BH27: 0.059414084 | BI27: 0.065157415 | BJ27: 0.077909969 | BK27: 0.07082455 | BL27: 0.067413357 | BM27: 0.049456582 | BN27: 0.040221902 | BO27: 0.043602568 | BP27: 0.057053113 | BQ27: 0.055309154 | BR27: 0.048314613 | BS27: 0.041981009 | BT27: 0.032739088 | BU27: 0.029693351 | BV27: 0.039089335 | BW27: 0.031331619 | BX27: 0.030216033 | BY27: 0.033622266 | BZ27: 0.046441183 | CA27: 0.051082618 | CB27: 0.053588777 | CC27: 0.054468453 | CD27: 0.052738091 | CE27: 0.014875349 | CF27: 0.05431698 | CG27: 0.067749783 | CH27: 0.061458309 | CI27: 0.050997599 | CJ27: 0.049674204 | CK27: 0.045752124 | CL27: 0.039659361 | CM27: 0.039266118 | CN27: 0.048038174 | CO27: 0.042689134 | CP27: 0.028812774 | CQ27: 0.034314364 | CR27: 0.049204095 | CS27: 0.039009574 | CT27: 0.0331661
A28: SPDividend Yield | B28: 0.035014354 | C28: 0.042854404 | D28: 0.060650873 | E28: 0.10154612 | F28: 0.090781216 | G28: 0.047905616 | H28: 0.048162084 | I28: 0.034568752 | J28: 0.033949156 | K28: 0.071154794 | L28: 0.054516129 | M28: 0.044611844 | N28: 0.062210142 | O28: 0.083159772 | P28: 0.07077026 | Q28: 0.052181169 | R28: 0.048658645 | S28: 0.038136488 | T28: 0.050082834 | U28: 0.053430378 | V28: 0.05725022 | W28: 0.061589404 | X28: 0.066449389 | Y28: 0.065759298 | Z28: 0.055323115 | AA28: 0.057541079 | AB28: 0.041945151 | AC28: 0.035057885 | AD28: 0.038676383 | AE28: 0.043826912 | AF28: 0.03273433 | AG28: 0.030623874 | AH28: 0.034369728 | AI28: 0.027407677 | AJ28: 0.033181777 | AK28: 0.029891819 | AL28: 0.02868186 | AM28: 0.028786714 | AN28: 0.035267714 | AO28: 0.030988368 | AP28: 0.028724853 | AQ28: 0.035283628 | AR28: 0.036114812 | AS28: 0.031717314 | AT28: 0.026692613 | AU28: 0.035584017 | AV28: 0.055175216 | AW28: 0.042867437 | AX28: 0.037175364 | AY28: 0.047796594 | AZ28: 0.053094908 | BA28: 0.052719862 | BB28: 0.04668245 | BC28: 0.053583431 | BD28: 0.049286422 | BE28: 0.043101838 | BF28: 0.045061495 | BG28: 0.038007281 | BH28: 0.03295133 | BI28: 0.035979123 | BJ28: 0.034144668 | BK28: 0.030349713 | BL28: 0.036261301 | BM28: 0.031740537 | BN28: 0.028645197 | BO28: 0.027094784 | BP28: 0.028539574 | BQ28: 0.022007553 | BR28: 0.01957471 | BS28: 0.015884026 | BT28: 0.013456479 | BU28: 0.011680604 | BV28: 0.01257103 | BW28: 0.013797816 | BX28: 0.017764303 | BY28: 0.015280196 | BZ28: 0.015652142 | CA28: 0.016748239 | CB28: 0.016662036 | CC28: 0.018044666 | CD28: 0.031722842 | CE28: 0.022938307 | CF28: 0.017995999 | CG28: 0.019794714 | CH28: 0.020194486 | CI28: 0.018470772 | CJ28: 0.018112579 | CK28: 0.02029807 | CL28: 0.019957695 | CM28: 0.017893296 | CN28: 0.02001691 | CO28: 0.017794762 | CP28: 0.016095453 | CQ28: 0.012901998 | CR28: 0.016590731 | CS28: 0.014794483 | CT28: 0.012114331
A29: trend g HLW | B29: NaN | C29: NaN | D29: NaN | E29: NaN | F29: NaN | G29: NaN | H29: NaN | I29: NaN | J29: NaN | K29: NaN | L29: NaN | M29: NaN | N29: NaN | O29: NaN | P29: NaN | Q29: NaN | R29: NaN | S29: NaN | T29: NaN | U29: NaN | V29: NaN | W29: NaN | X29: NaN | Y29: NaN | Z29: NaN | AA29: NaN | AB29: NaN | AC29: NaN | AD29: NaN | AE29: NaN | AF29: NaN | AG29: NaN | AH29: NaN | AI29: ='rstar estimates'!B22 -> 5.0535728 | AJ29: ='rstar estimates'!C22 -> 3.895209 | AK29: ='rstar estimates'!D22 -> 3.887629 | AL29: ='rstar estimates'!E22 -> 3.9847854 | AM29: ='rstar estimates'!F22 -> 4.7193122 | AN29: ='rstar estimates'!G22 -> 4.5944173 | AO29: ='rstar estimates'!H22 -> 4.3377748 | AP29: ='rstar estimates'!I22 -> 4.3117097 | ... CT29: ='rstar estimates'!BM22 -> 2.4565514
A30: Bauer Rudebusch rstar (end of year) | B30: NaN | C30: NaN | D30: NaN | E30: NaN | F30: NaN | G30: NaN | H30: NaN | I30: NaN | J30: NaN | K30: NaN | L30: NaN | M30: NaN | N30: NaN | O30: NaN | P30: NaN | Q30: NaN | R30: NaN | S30: NaN | T30: NaN | U30: NaN | V30: NaN | W30: NaN | X30: NaN | Y30: NaN | Z30: NaN | AA30: NaN | AB30: NaN | AC30: NaN | AD30: NaN | AE30: NaN | AF30: NaN | AG30: NaN | AH30: NaN | AI30: NaN | AJ30: NaN | AK30: NaN | AL30: NaN | AM30: NaN | AN30: NaN | AO30: NaN | AP30: NaN | AQ30: NaN | AR30: NaN | AS30: 2.1150066 | AT30: 2.1349668 | AU30: 2.1929508 | AV30: 1.7969603 | AW30: 1.7611073 | AX30: 1.6244953 | AY30: 1.5726897 | AZ30: 1.7944572 | BA30: 1.8939945 | BB30: 2.02581 | BC30: 2.0749039 | BD30: 1.9782419 | BE30: 2.2455671 | BF30: 2.4474308 | BG30: 2.4583929 | BH30: 2.379612 | BI30: 2.4438086 | BJ30: 2.6063283 | BK30: 2.6222987 | BL30: 2.492771 | BM30: 2.3812134 | BN30: 2.1966115 | BO30: 2.048737 | BP30: 2.1657986 | BQ30: 2.1921596 | BR30: 2.26921 | BS30: 2.3776836 | BT30: 2.5032879 | BU30: 2.6051738 | BV30: 2.692727 | BW30: 2.4086588 | BX30: 2.1730293 | BY30: 2.0319014 | BZ30: 1.8900346 | CA30: 1.9121786 | CB30: 1.9892265 | CC30: 1.8565944 | CD30: 1.1940393 | CE30: 1.1300649 | CF30: 0.91496597 | CG30: 0.84017309 | CH30: 0.68972432 | CI30: 0.68480369 | CJ30: 0.62333976 | CK30: 0.59253781 | CL30: 0.52135301 | CM30: 0.53593275 | CN30: NaN | CO30: NaN | CP30: NaN | CQ30: NaN | CR30: NaN | CS30: NaN | CT30: NaN
C34: =+C1 -> 1929 | D34: =+D1 -> 1930 | E34: =+E1 -> 1931 | F34: =+F1 -> 1932 | G34: =+G1 -> 1933 | H34: =+H1 -> 1934 | I34: =+I1 -> 1935 | J34: =+J1 -> 1936 | ... CT34: =+CT1 -> 2024
B35: tax/NOS | C35: =+C8/C6 -> 0.11064278 | D35: =+D8/D6 -> 0.090997514 | E35: =+E8/E6 -> 0.10198648 | F35: =+F8/F6 -> 0.22989196 | G35: =+G8/G6 -> 0.37240886 | H35: =+H8/H6 -> 0.1746069 | I35: =+I8/I6 -> 0.1653338 | J35: =+J8/J6 -> 0.17976525 | ... CT35: =+CT8/CT6 -> 0.18469093
B36: max rate | C36: =+C14 -> 0.11 | D36: =+D14 -> 0.12 | E36: =+E14 -> 0.12 | F36: =+F14 -> 0.1375 | G36: =+G14 -> 0.1375 | H36: =+H14 -> 0.1375 | I36: =+I14 -> 0.1375 | J36: =+J14 -> 0.15 | ... CT36: =+CT14 -> 0.21
B37: (tax+transfers)/NOS | C37: =+(C7+C8)/C6 -> 0.13941801 | D37: =+(D7+D8)/D6 -> 0.12925538 | E37: =+(E7+E8)/E6 -> 0.18513209 | F37: =+(F7+F8)/F6 -> 0.484994 | G37: =+(G7+G8)/G6 -> 0.66118656 | H37: =+(H7+H8)/H6 -> 0.26613471 | I37: =+(I7+I8)/I6 -> 0.22931154 | J37: =+(J7+J8)/J6 -> 0.22480225 | ... CT37: =+(CT7+CT8)/CT6 -> 0.25290736
B38: IBT+bt/gva | C38: =+(C5+C7)/C2 -> 0.061197679 | D38: =+(D5+D7)/D2 -> 0.070384823 | E38: =+(E5+E7)/E2 -> 0.085821487 | F38: =+(F5+F7)/F2 -> 0.12084993 | G38: =+(G5+G7)/G2 -> 0.14403185 | H38: =+(H5+H7)/H2 -> 0.13373134 | I38: =+(I5+I7)/I2 -> 0.1217595 | J38: =+(J5+J7)/J2 -> 0.11040633 | ... CT38: =+(CT5+CT7)/CT2 -> 0.088558871
B41: Net Invest/QK | C41: =(C9-C3)/C11 -> 0.027637338 | D41: =(D9-D3)/D11 -> 0.016630019 | E41: =(E9-E3)/E11 -> -0.0040882894 | F41: =(F9-F3)/F11 -> -0.018325132 | G41: =(G9-G3)/G11 -> -0.017783858 | H41: =(H9-H3)/H11 -> -0.011745856 | I41: =(I9-I3)/I11 -> -0.007067711 | J41: =(J9-J3)/J11 -> 0.0036870437 | ... CT41: =(CT9-CT3)/CT11 -> 0.026263444
B42: Tobins Q | C42: =C12/C11 - 1 -> 0.54919569 | D42: =D12/D11 - 1 -> 0.30999636 | E42: =E12/E11 - 1 -> -0.059102579 | F42: =F12/F11 - 1 -> -0.13334591 | G42: =G12/G11 - 1 -> 0.12782535 | H42: =H12/H11 - 1 -> -0.029814928 | I42: =I12/I11 - 1 -> 0.28861021 | J42: =J12/J11 - 1 -> 0.49244023 | ... CT42: =CT12/CT11 - 1 -> 1.9393896
B44: QK3 | C44: =3*C41+1 -> 1.082912 | D44: =3*D41+1 -> 1.0498901 | E44: =3*E41+1 -> 0.98773513 | F44: =3*F41+1 -> 0.9450246 | G44: =3*G41+1 -> 0.94664843 | H44: =3*H41+1 -> 0.96476243 | I44: =3*I41+1 -> 0.97879687 | J44: =3*J41+1 -> 1.0110611 | ... CT44: =3*CT41+1 -> 1.0787903
B45: QK8 | C45: =8*C41+1 -> 1.2210987 | D45: =8*D41+1 -> 1.1330402 | E45: =8*E41+1 -> 0.96729368 | F45: =8*F41+1 -> 0.85339894 | G45: =8*G41+1 -> 0.85772914 | H45: =8*H41+1 -> 0.90603315 | I45: =8*I41+1 -> 0.94345831 | J45: =8*J41+1 -> 1.0294963 | ... CT45: =8*CT41+1 -> 1.2101076
B47: VPi0 | C47: =C12/C2-C11/C2 -> 1.0623569 | D47: =D12/D2-D11/D2 -> 0.64962955 | E47: =E12/E2-E11/E2 -> -0.14171595 | F47: =F12/F2-F11/F2 -> -0.40560878 | G47: =G12/G2-G11/G2 -> 0.40677624 | H47: =H12/H2-H11/H2 -> -0.077210874 | I47: =I12/I2-I11/I2 -> 0.6705621 | J47: =J12/J2-J11/J2 -> 1.0941362 | ... CT47: =CT12/CT2-CT11/CT2 -> 3.1562817
...

Sheet B1
A1: Download Page | F1: Z.1 Statistical Release for Jan 09, 2026
A2: Descriptions: | B2: Unit: | C2: Multiplier: | D2: Currency: | E2: Unique Identifier: | F2: Series Name: | G2: 1945 | H2: 1946 | I2: 1947 | J2: 1948 | K2: 1949 | L2: 1950 | M2: 1951 | N2: 1952 | O2: 1953 | P2: 1954 | Q2: 1955 | R2: 1956 | S2: 1957 | T2: 1958 | U2: 1959 | V2: 1960 | W2: 1961 | X2: 1962 | Y2: 1963 | Z2: 1964 | AA2: 1965 | AB2: 1966 | AC2: 1967 | AD2: 1968 | AE2: 1969 | AF2: 1970 | AG2: 1971 | AH2: 1972 | AI2: 1973 | AJ2: 1974 | AK2: 1975 | AL2: 1976 | AM2: 1977 | AN2: 1978 | AO2: 1979 | AP2: 1980 | AQ2: 1981 | AR2: 1982 | AS2: 1983 | AT2: 1984 | AU2: 1985 | AV2: 1986 | AW2: 1987 | AX2: 1988 | AY2: 1989 | AZ2: 1990 | BA2: 1991 | BB2: 1992 | BC2: 1993 | BD2: 1994 | BE2: 1995 | BF2: 1996 | BG2: 1997 | BH2: 1998 | BI2: 1999 | BJ2: 2000 | BK2: 2001 | BL2: 2002 | BM2: 2003 | BN2: 2004 | BO2: 2005 | BP2: 2006 | BQ2: 2007 | BR2: 2008 | BS2: 2009 | BT2: 2010 | BU2: 2011 | BV2: 2012 | BW2: 2013 | BX2: 2014 | BY2: 2015 | BZ2: 2016 | CA2: 2017 | CB2: 2018 | CC2: 2019 | CD2: 2020 | CE2: 2021 | CF2: 2022 | CG2: 2023 | CH2: 2024
A3: All sectors; U.S. wealth | B3: Currency | C3: 1000000 | D3: USD | E3: Z1/Z1/FL892090005.A | F3: FL892090005.A | G3: 733273 | H3: 817833 | I3: 934935 | J3: 991725 | K3: 1013747 | L3: 1120186 | M3: 1269077 | N3: 1317785 | O3: 1351999 | P3: 1497113 | Q3: 1679481 | R3: 1832498 | S3: 1866771 | T3: 2080972 | U3: 2210496 | V3: 2287245 | W3: 2521742 | X3: 2598968 | Y3: 2726472 | Z3: 2911977 | AA3: 3124583 | AB3: 3243599 | AC3: 3557415 | AD3: 3974923 | AE3: 4088663 | AF3: 4322288 | AG3: 4718697 | AH3: 5294069 | AI3: 5599547 | AJ3: 5835321 | AK3: 6602817 | AL3: 7288342 | AM3: 7903176 | AN3: 8888113 | AO3: 10272149 | AP3: 11792350 | AQ3: 12769304 | AR3: 13335352 | AS3: 14148311 | AT3: 15109572 | AU3: 16485542 | AV3: 17875263 | AW3: 19004781 | AX3: 20533955 | AY3: 22293729 | AZ3: 22775596 | BA3: 24130502 | BB3: 25093678 | BC3: 26414440 | BD3: 27452078 | BE3: 29810038 | BF3: 31995017 | BG3: 35684048 | BH3: 39569603 | BI3: 45125576 | BJ3: 45817440 | BK3: 46537331 | BL3: 45990464 | BM3: 51334751 | BN3: 57772107 | BO3: 63513873 | BP3: 68590785 | BQ3: 69637948 | BR3: 59655182 | BS3: 58484178 | BT3: 63014150 | BU3: 61929247 | BV3: 65945859 | BW3: 75557851 | BX3: 80021752 | BY3: 82238878 | BZ3: 87161969 | CA3: 95332022 | CB3: 94848037 | CC3: 103033483 | CD3: 113914917 | CE3: 136205372 | CF3: 135285879 | CG3: 144557112 | CH3: 156707266
A4: Households and nonprofit organizations; nonfinancial assets | B4: Currency | C4: 1000000 | D4: USD | E4: Z1/Z1/LM152010005.A | F4: LM152010005.A | G4: 189327 | H4: 220716 | I4: 280815 | J4: 313686 | K4: 340071 | L4: 387297 | M4: 430932 | N4: 463998 | O4: 493418 | P4: 520894 | Q4: 565453 | R4: 608073 | S4: 643776 | T4: 670313 | U4: 706020 | V4: 737552 | W4: 769614 | X4: 803569 | Y4: 839163 | Z4: 884104 | AA4: 930933 | AB4: 1005985 | AC4: 1074444 | AD4: 1200814 | AE4: 1308558 | AF4: 1390677 | AG4: 1517841 | AH4: 1714199 | AI4: 1943148 | AJ4: 2064417 | AK4: 2286518 | AL4: 2543119 | AM4: 2947334 | AN4: 3407984 | AO4: 3961948 | AP4: 4451130 | AQ4: 4916768 | AR4: 5148139 | AS4: 5444411 | AT4: 6150304 | AU4: 6937161 | AV4: 7644160 | AW4: 8330141 | AX4: 9094409 | AY4: 9817681 | AZ4: 10083770 | BA4: 10308657 | BB4: 10665051 | BC4: 11136594 | BD4: 11662709 | BE4: 11929586 | BF4: 12484792 | BG4: 13201651 | BH4: 14292512 | BI4: 15542198 | BJ4: 17549453 | BK4: 19536847 | BL4: 21309764 | BM4: 23178254 | BN4: 26438362 | BO4: 29769560 | BP4: 31090978 | BQ4: 30587677 | BR4: 28105337 | BS4: 26046008 | BT4: 25650841 | BU4: 25220683 | BV4: 25840518 | BW4: 27969505 | BX4: 29654637 | BY4: 31556587 | BZ4: 33665006 | CA4: 35879789 | CB4: 37209025 | CC4: 38517398 | CD4: 42808158 | CE4: 51375030 | CF4: 54832175 | CG4: 57680864 | CH4: 60080508
A5: Households and nonprofit organizations; real estate at market value | B5: Currency | C5: 1000000 | D5: USD | E5: Z1/Z1/LM155035005.A | F5: LM155035005.A | G5: 134635 | H5: 158074 | I5: 206381 | J5: 229359 | K5: 246931 | L5: 278126 | M5: 308963 | N5: 334895 | O5: 355919 | P5: 379599 | Q5: 414487 | R5: 445773 | S5: 471674 | T5: 493819 | U5: 521544 | V5: 547589 | W5: 576368 | X5: 603604 | Y5: 628622 | Z5: 662499 | AA5: 696286 | AB5: 748935 | AC5: 794221 | AD5: 889605 | AE5: 968674 | AF5: 1025204 | AG5: 1127739 | AH5: 1290675 | AI5: 1472632 | AJ5: 1517696 | AK5: 1684206 | AL5: 1880025 | AM5: 2211304 | AN5: 2577511 | AO5: 3025997 | AP5: 3413722 | AQ5: 3803851 | AR5: 3989640 | AS5: 4209413 | AT5: 4816923 | AU5: 5492906 | AV5: 6049418 | AW5: 6598723 | AX5: 7207766 | AY5: 7797521 | AZ5: 7941478 | BA5: 8080372 | BB5: 8353177 | BC5: 8711537 | BD5: 9110695 | BE5: 9267737 | BF5: 9721072 | BG5: 10341382 | BH5: 11303625 | BI5: 12381006 | BJ5: 14160428 | BK5: 15970953 | BL5: 17564511 | BM5: 19264275 | BN5: 22283537 | BO5: 25388489 | BP5: 26497066 | BQ5: 25795258 | BR5: 23190081 | BS5: 21115293 | BT5: 20719405 | BU5: 20146017 | BV5: 20652228 | BW5: 22690165 | BX5: 24266395 | BY5: 25995204 | BZ5: 27920752 | CA5: 29972160 | CB5: 31057948 | CC5: 32126419 | CD5: 36020399 | CE5: 43564200 | CF5: 46325329 | CG5: 48912521 | CH5: 51011988
A6: Nonprofit organizations; equipment, current cost basis | B6: Currency | C6: 1000000 | D6: USD | E6: Z1/Z1/LM165015205.A | F6: LM165015205.A | G6: 436 | H6: 590 | I6: 768 | J6: 944 | K6: 1043 | L6: 1346 | M6: 1592 | N6: 1728 | O6: 1980 | P6: 2160 | Q6: 2412 | R6: 2726 | S6: 3050 | T6: 3263 | U6: 3550 | V6: 3760 | W6: 3989 | X6: 4245 | Y6: 4529 | Z6: 4873 | AA6: 5257 | AB6: 5795 | AC6: 6317 | AD6: 6876 | AE6: 7605 | AF6: 8354 | AG6: 9063 | AH6: 10558 | AI6: 12517 | AJ6: 16435 | AK6: 19180 | AL6: 21838 | AM6: 24480 | AN6: 27912 | AO6: 31525 | AP6: 36150 | AQ6: 40085 | AR6: 42670 | AS6: 45262 | AT6: 48100 | AU6: 50419 | AV6: 54289 | AW6: 58601 | AX6: 63306 | AY6: 68558 | AZ6: 74319 | BA6: 78767 | BB6: 82840 | BC6: 85114 | BD6: 87566 | BE6: 90118 | BF6: 91444 | BG6: 94611 | BH6: 103614 | BI6: 114288 | BJ6: 127343 | BK6: 140201 | BL6: 154827 | BM6: 167565 | BN6: 183824 | BO6: 197724 | BP6: 215065 | BQ6: 231681 | BR6: 255136 | BS6: 268585 | BT6: 284802 | BU6: 307356 | BV6: 326848 | BW6: 354638 | BX6: 380723 | BY6: 407721 | BZ6: 434808 | CA6: 457951 | CB6: 485525 | CC6: 514573 | CD6: 543747 | CE6: 581703 | CF6: 622277 | CG6: 653471 | CH6: 681682
A7: Nonprofit organizations; nonresidential intellectual property products, current cost basis | B7: Currency | C7: 1000000 | D7: USD | E7: Z1/Z1/LM165013765.A | F7: LM165013765.A | G7: 257 | H7: 292 | I7: 310 | J7: 310 | K7: 315 | L7: 345 | M7: 366 | N7: 375 | O7: 394 | P7: 417 | Q7: 455 | R7: 502 | S7: 555 | T7: 628 | U7: 710 | V7: 784 | W7: 882 | X7: 1011 | Y7: 1168 | Z7: 1334 | AA7: 1522 | AB7: 1738 | AC7: 1984 | AD7: 2274 | AE7: 2568 | AF7: 2862 | AG7: 3143 | AH7: 3458 | AI7: 3967 | AJ7: 4615 | AK7: 5136 | AL7: 5735 | AM7: 6434 | AN7: 7463 | AO7: 8850 | AP7: 10389 | AQ7: 12053 | AR7: 13405 | AS7: 14644 | AT7: 15698 | AU7: 16706 | AV7: 18069 | AW7: 20155 | AX7: 23011 | AY7: 26019 | AZ7: 28931 | BA7: 32071 | BB7: 35566 | BC7: 37695 | BD7: 40312 | BE7: 42425 | BF7: 44347 | BG7: 47697 | BH7: 51510 | BI7: 55811 | BJ7: 59926 | BK7: 61393 | BL7: 64242 | BM7: 68813 | BN7: 72782 | BO7: 77077 | BP7: 80588 | BQ7: 85949 | BR7: 93873 | BS7: 101997 | BT7: 111132 | BU7: 122656 | BV7: 134002 | BW7: 147368 | BX7: 155759 | BY7: 163037 | BZ7: 172718 | CA7: 182042 | CB7: 193947 | CC7: 205063 | CD7: 221738 | CE7: 233171 | CF7: 245254 | CG7: 258301 | CH7: 275648
A8: Households and nonprofit organizations; consumer durable goods, current cost basis | B8: Currency | C8: 1000000 | D8: USD | E8: Z1/Z1/LM155111005.A | F8: LM155111005.A | G8: 53999 | H8: 61760 | I8: 73356 | J8: 83073 | K8: 91782 | L8: 107480 | M8: 120011 | N8: 127000 | O8: 135125 | P8: 138718 | Q8: 148099 | R8: 159072 | S8: 168497 | T8: 172603 | U8: 180216 | V8: 185419 | W8: 188375 | X8: 194709 | Y8: 204844 | Z8: 215398 | AA8: 227868 | AB8: 249517 | AC8: 271922 | AD8: 302059 | AE8: 329711 | AF8: 354257 | AG8: 377896 | AH8: 409508 | AI8: 454032 | AJ8: 525671 | AK8: 577996 | AL8: 635521 | AM8: 705116 | AN8: 795098 | AO8: 895576 | AP8: 990869 | AQ8: 1060779 | AR8: 1102424 | AS8: 1175092 | AT8: 1269583 | AU8: 1377130 | AV8: 1522384 | AW8: 1652662 | AX8: 1800326 | AY8: 1925583 | AZ8: 2039042 | BA8: 2117447 | BB8: 2193468 | BC8: 2302248 | BD8: 2424136 | BE8: 2529306 | BF8: 2627929 | BG8: 2717961 | BH8: 2833763 | BI8: 2991093 | BJ8: 3201756 | BK8: 3364300 | BL8: 3526184 | BM8: 3677601 | BN8: 3898219 | BO8: 4106270 | BP8: 4298259 | BQ8: 4474789 | BR8: 4566247 | BS8: 4560133 | BT8: 4535502 | BU8: 4644654 | BV8: 4727440 | BW8: 4777334 | BX8: 4851760 | BY8: 4990625 | BZ8: 5136728 | CA8: 5267636 | CB8: 5471605 | CC8: 5671343 | CD8: 6022274 | CE8: 6995956 | CF8: 7639315 | CG8: 7856571 | CH8: 8111190
A9: Nonfinancial noncorporate business; nonfinancial assets | B9: Currency | C9: 1000000 | D9: USD | E9: Z1/Z1/LM112010005.A | F9: LM112010005.A | G9: 188688 | H9: 227819 | I9: 262959 | J9: 281246 | K9: 284459 | L9: 304098 | M9: 333808 | N9: 336953 | O9: 337207 | P9: 344489 | Q9: 359453 | R9: 378823 | S9: 393645 | T9: 409859 | U9: 419022 | V9: 434722 | W9: 457533 | X9: 482177 | Y9: 495124 | Z9: 521651 | AA9: 556908 | AB9: 597837 | AC9: 631468 | AD9: 685644 | AE9: 734613 | AF9: 778637 | AG9: 861877 | AH9: 969757 | AI9: 1137615 | AJ9: 1292563 | AK9: 1413727 | AL9: 1568517 | AM9: 1762657 | AN9: 2038862 | AO9: 2378693 | AP9: 2689173 | AQ9: 2883132 | AR9: 3005164 | AS9: 3120880 | AT9: 3221698 | AU9: 3353925 | AV9: 3498188 | AW9: 3669597 | AX9: 3877704 | AY9: 4070053 | AZ9: 4158524 | BA9: 4084665 | BB9: 4031762 | BC9: 4147907 | BD9: 4349727 | BE9: 4528496 | BF9: 4760461 | BG9: 5203809 | BH9: 5510571 | BI9: 5909950 | BJ9: 6393538 | BK9: 6634585 | BL9: 7078073 | BM9: 7562615 | BN9: 8602156 | BO9: 9734904 | BP9: 10511942 | BQ9: 10699790 | BR9: 9807562 | BS9: 8552329 | BT9: 9021884 | BU9: 9197054 | BV9: 9733116 | BW9: 10604929 | BX9: 11335238 | BY9: 11957273 | BZ9: 12599108 | CA9: 13363327 | CB9: 13874943 | CC9: 14670219 | CD9: 15673569 | CE9: 18261928 | CF9: 19102278 | CG9: 18758406 | CH9: 19036293
A10: Nonfinancial noncorporate business; real estate at market value | B10: Currency | C10: 1000000 | D10: USD | E10: Z1/Z1/LM115035005.A | F10: LM115035005.A | G10: 151676 | H10: 179671 | I10: 206256 | J10: 218473 | K10: 223629 | L10: 236563 | M10: 255779 | N10: 262603 | O10: 264204 | P10: 271288 | Q10: 287208 | R10: 302998 | S10: 313203 | T10: 323570 | U10: 334803 | V10: 349081 | W10: 370084 | X10: 391707 | Y10: 405397 | Z10: 430762 | AA10: 458451 | AB10: 493570 | AC10: 522958 | AD10: 569262 | AE10: 609003 | AF10: 648063 | AG10: 719630 | AH10: 812021 | AI10: 952736 | AJ10: 1092686 | AK10: 1196958 | AL10: 1341057 | AM10: 1512676 | AN10: 1742627 | AO10: 2033457 | AP10: 2313816 | AQ10: 2485585 | AR10: 2589754 | AS10: 2704845 | AT10: 2789414 | AU10: 2912260 | AV10: 3054746 | AW10: 3208385 | AX10: 3388668 | AY10: 3557102 | AZ10: 3627015 | BA10: 3558666 | BB10: 3491595 | BC10: 3598151 | BD10: 3775833 | BE10: 3938765 | BF10: 4118650 | BG10: 4544029 | BH10: 4844518 | BI10: 5209030 | BJ10: 5648078 | BK10: 5875493 | BL10: 6287628 | BM10: 6736988 | BN10: 7724369 | BO10: 8800140 | BP10: 9518182 | BQ10: 9635008 | BR10: 8706511 | BS10: 7476211 | BT10: 7903416 | BU10: 8019481 | BV10: 8528165 | BW10: 9340514 | BX10: 10018388 | BY10: 10641128 | BZ10: 11275644 | CA10: 11987975 | CB10: 12451733 | CC10: 13198031 | CD10: 14164755 | CE10: 16605068 | CF10: 17293612 | CG10: 16866688 | CH10: 17050499
A11: Nonfinancial noncorporate business; equipment, current cost basis | B11: Currency | C11: 1000000 | D11: USD | E11: Z1/Z1/LM115015205.A | F11: LM115015205.A | G11: 10964 | H11: 13074 | I11: 17090 | J11: 21750 | K11: 23749 | L11: 28420 | M11: 31385 | N11: 32717 | O11: 34704 | P11: 35044 | Q11: 38014 | R11: 40430 | S11: 42761 | T11: 43678 | U11: 45090 | V11: 45487 | W11: 45398 | X11: 46183 | Y11: 47571 | Z11: 49566 | AA11: 52385 | AB11: 56839 | AC11: 60640 | AD11: 64814 | AE11: 69951 | AF11: 75670 | AG11: 80391 | AH11: 85049 | AI11: 94515 | AJ11: 114461 | AK11: 127379 | AL11: 139076 | AM11: 153768 | AN11: 173992 | AO11: 202086 | AP11: 227609 | AQ11: 253944 | AR11: 265258 | AS11: 268073 | AT11: 275474 | AU11: 283730 | AV11: 294536 | AW11: 303632 | AX11: 319657 | AY11: 333525 | AZ11: 340708 | BA11: 341091 | BB11: 341468 | BC11: 347761 | BD11: 359958 | BE11: 373811 | BF11: 384648 | BG11: 394954 | BH11: 407455 | BI11: 424173 | BJ11: 446601 | BK11: 463398 | BL11: 478900 | BM11: 492373 | BN11: 527455 | BO11: 562305 | BP11: 607005 | BQ11: 642030 | BR11: 678964 | BS11: 671933 | BT11: 682617 | BU11: 707028 | BV11: 731801 | BW11: 768848 | BX11: 795061 | BY11: 811007 | BZ11: 819333 | CA11: 839201 | CB11: 868464 | CC11: 894903 | CD11: 920830 | CE11: 998940 | CF11: 1084767 | CG11: 1124436 | CH11: 1161744
A12: Nonfinancial noncorporate business; nonresidential intellectual property products, current cost basis | B12: Currency | C12: 1000000 | D12: USD | E12: Z1/Z1/LM115013765.A | F12: LM115013765.A | G12: 1942 | H12: 2162 | I12: 2507 | J12: 2667 | K12: 2777 | L12: 3009 | M12: 3103 | N12: 3221 | O12: 3430 | P12: 3603 | Q12: 3850 | R12: 4110 | S12: 4392 | T12: 4596 | U12: 4964 | V12: 5154 | W12: 5480 | X12: 5680 | Y12: 5958 | Z12: 6186 | AA12: 6463 | AB12: 6690 | AC12: 7023 | AD12: 7321 | AE12: 7756 | AF12: 8142 | AG12: 8216 | AH12: 8279 | AI12: 8450 | AJ12: 8953 | AK12: 9264 | AL12: 9686 | AM12: 10008 | AN12: 10959 | AO12: 12202 | AP12: 13666 | AQ12: 15311 | AR12: 16566 | AS12: 17915 | AT12: 19855 | AU12: 22012 | AV12: 24417 | AW12: 28105 | AX12: 33847 | AY12: 39929 | AZ12: 46014 | BA12: 51818 | BB12: 57225 | BC12: 62097 | BD12: 67201 | BE12: 72484 | BF12: 77023 | BG12: 82819 | BH12: 90612 | BI12: 101839 | BJ12: 114050 | BK12: 121009 | BL12: 128475 | BM12: 136837 | BN12: 143903 | BO12: 154293 | BP12: 164458 | BQ12: 175832 | BR12: 183941 | BS12: 186573 | BT12: 191485 | BU12: 196795 | BV12: 202243 | BW12: 217714 | BX12: 229951 | BY12: 243405 | BZ12: 252310 | CA12: 276603 | CB12: 293623 | CC12: 319054 | CD12: 347515 | CE12: 372475 | CF12: 412860 | CG12: 449464 | CH12: 484930
A13: Nonfinancial noncorporate business; inventories | B13: Currency | C13: 1000000 | D13: USD | E13: Z1/Z1/LM115020005.A | F13: LM115020005.A | G13: 24106 | H13: 32912 | I13: 37106 | J13: 38356 | K13: 34304 | L13: 36106 | M13: 43541 | N13: 38412 | O13: 34869 | P13: 34554 | Q13: 30381 | R13: 31285 | S13: 33289 | T13: 38015 | U13: 34165 | V13: 35000 | W13: 36571 | X13: 38607 | Y13: 36198 | Z13: 35137 | AA13: 39609 | AB13: 40738 | AC13: 40847 | AD13: 44247 | AE13: 47903 | AF13: 46762 | AG13: 53640 | AH13: 64408 | AI13: 81914 | AJ13: 76463 | AK13: 80126 | AL13: 78698 | AM13: 86205 | AN13: 111284 | AO13: 130948 | AP13: 134082 | AQ13: 128292 | AR13: 133586 | AS13: 130047 | AT13: 136955 | AU13: 135923 | AV13: 124489 | AW13: 129475 | AX13: 135532 | AY13: 139497 | AZ13: 144787 | BA13: 133090 | BB13: 141474 | BC13: 139898 | BD13: 146735 | BE13: 143436 | BF13: 180140 | BG13: 182007 | BH13: 167986 | BI13: 174908 | BJ13: 184809 | BK13: 174685 | BL13: 183070 | BM13: 196417 | BN13: 206429 | BO13: 218166 | BP13: 222297 | BQ13: 246920 | BR13: 238146 | BS13: 217612 | BT13: 244366 | BU13: 273750 | BV13: 270907 | BW13: 277853 | BX13: 291838 | BY13: 261733 | BZ13: 251821 | CA13: 259548 | CB13: 261123 | CC13: 258231 | CD13: 240469 | CE13: 285445 | CF13: 311039 | CG13: 317818 | CH13: 339120
A14: Security brokers and dealers; proprietors' equity in noncorporate business | B14: Currency | C14: 1000000 | D14: USD | E14: Z1/Z1/LM662090003.A | F14: LM662090003.A | G14: 0 | H14: 0 | I14: 0 | J14: 0 | K14: 0 | L14: 0 | M14: 0 | N14: 0 | O14: 0 | P14: 0 | Q14: 0 | R14: 0 | S14: 0 | T14: 0 | U14: 0 | V14: 0 | W14: 0 | X14: 0 | Y14: 0 | Z14: 0 | AA14: 0 | AB14: 0 | AC14: 0 | AD14: 0 | AE14: 0 | AF14: 0 | AG14: 0 | AH14: 0 | AI14: 950 | AJ14: 1706 | AK14: 2135 | AL14: 1943 | AM14: 1711 | AN14: 1973 | AO14: 2694 | AP14: 2172 | AQ14: 2191 | AR14: 2994 | AS14: 3642 | AT14: 3966 | AU14: 4718 | AV14: 6398 | AW14: 5877 | AX14: 6578 | AY14: 5788 | AZ14: 4524 | BA14: 5680 | BB14: 5889 | BC14: 6966 | BD14: 5868 | BE14: 7005 | BF14: 7837 | BG14: 10911 | BH14: 11257 | BI14: 13774 | BJ14: 14609 | BK14: 19232 | BL14: 18595 | BM14: 19076 | BN14: 18810 | BO14: 18965 | BP14: 16977 | BQ14: 22230 | BR14: 21785 | BS14: 23035 | BT14: 29197 | BU14: 27446 | BV14: 37886 | BW14: 40794 | BX14: 45121 | BY14: 50404 | BZ14: 67741 | CA14: 68693 | CB14: 78230 | CC14: 83475 | CD14: 90334 | CE14: 106104 | CF14: 109761 | CG14: 123829 | CH14: 140600
... A33: All sectors; U.S. wealth | B33: Currency | C33: 1000000 | D33: USD | E33: Z1/Z1/FL892090005.A | F33: FL892090005.A | G33: 733273 | H33: 817833 | I33: 934935 | J33: 991725 | K33: 1013747 | L33: 1120186 | M33: 1269077 | N33: 1317785 | O33: 1351999 | P33: 1497113 | Q33: 1679481 | R33: 1832498 | S33: 1866771 | T33: 2080972 | U33: 2210496 | V33: 2287245 | W33: 2521742 | X33: 2598968 | Y33: 2726472 | Z33: 2911977 | AA33: 3124583 | AB33: 3243599 | AC33: 3557415 | AD33: 3974923 | AE33: 4088663 | AF33: 4322288 | AG33: 4718697 | AH33: 5294069 | AI33: 5599547 | AJ33: 5835321 | AK33: 6602817 | AL33: 7288342 | AM33: 7903176 | AN33: 8888113 | AO33: 10272149 | AP33: 11792350 | AQ33: 12769304 | AR33: 13335352 | AS33: 14148311 | AT33: 15109572 | AU33: 16485542 | AV33: 17875263 | AW33: 19004781 | AX33: 20533955 | AY33: 22293729 | AZ33: 22775596 | BA33: 24130502 | BB33: 25093678 | BC33: 26414440 | BD33: 27452078 | BE33: 29810038 | BF33: 31995017 | BG33: 35684048 | BH33: 39569603 | BI33: 45125576 | BJ33: 45817440 | BK33: 46537331 | BL33: 45990464 | BM33: 51334751 | BN33: 57772107 | BO33: 63513873 | BP33: 68590785 | BQ33: 69637948 | BR33: 59655182 | BS33: 58484178 | BT33: 63014150 | BU33: 61929247 | BV33: 65945859 | BW33: 75557851 | BX33: 80021752 | BY33: 82238878 | BZ33: 87161969 | CA33: 95332022 | CB33: 94848037 | CC33: 103033483 | CD33: 113914917 | CE33: 136205372 | CF33: 135285879 | CG33: 144557112 | CH33: 156707266
A34: All sectors; U.S. wealth | B34: Currency | C34: 1000000 | D34: USD | E34: Z1/Z1/FC892090005.A | F34: FC892090005.A | H34: 84560 | I34: 117102 | J34: 56791 | K34: 22022 | L34: 106439 | M34: 148891 | N34: 48708 | O34: 34214 | P34: 145114 | Q34: 182368 | R34: 153017 | S34: 34273 | T34: 214201 | U34: 129524 | V34: 76749 | W34: 234497 | X34: 77226 | Y34: 127504 | Z34: 185505 | AA34: 212606 | AB34: 119016 | AC34: 313816 | AD34: 417508 | AE34: 113740 | AF34: 233625 | AG34: 396409 | AH34: 575372 | AI34: 305478 | AJ34: 235774 | AK34: 767496 | AL34: 685525 | AM34: 614834 | AN34: 984937 | AO34: 1384036 | AP34: 1520201 | AQ34: 976954 | AR34: 566048 | AS34: 812959 | AT34: 961261 | AU34: 1375970 | AV34: 1389721 | AW34: 1129518 | AX34: 1529174 | AY34: 1759774 | AZ34: 481867 | BA34: 1354906 | BB34: 963176 | BC34: 1320762 | BD34: 1037638 | BE34: 2357960 | BF34: 2184979 | BG34: 3689031 | BH34: 3885555 | BI34: 5555972 | BJ34: 691865 | BK34: 719891 | BL34: -546867 | BM34: 5344287 | BN34: 6437356 | BO34: 5741766 | BP34: 5076912 | BQ34: 1047163 | BR34: -9982766 | BS34: -1171004 | BT34: 4529971 | BU34: -1084902 | BV34: 4016611 | BW34: 9611992 | BX34: 4463901 | BY34: 2217126 | BZ34: 4923091 | CA34: 8170053 | CB34: -483985 | CC34: 8185446 | CD34: 10881434 | CE34: 22290455 | CF34: -919493 | CG34: 9271233 | CH34: 12150153
A35: All sectors; U.S. wealth | B35: Percent | C35: 1000000 | D35: USD | E35: Z1/Z1/PC892090005.A | F35: PC892090005.A | H35: 11.531812 | I35: 14.31851 | J35: 6.0743025 | K35: 2.2205495 | L35: 10.499587 | M35: 13.291607 | N35: 3.838065 | O35: 2.5963264 | P35: 10.733292 | Q35: 12.181312 | R35: 9.1109694 | S35: 1.8702885 | T35: 11.474412 | U35: 6.2242068 | V35: 3.4720262 | W35: 10.252378 | X35: 3.0624069 | Y35: 4.9059473 | Z35: 6.8038476 | AA35: 7.3010879 | AB35: 3.8090203 | AC35: 9.6749321 | AD35: 11.736275 | AE35: 2.8614391 | AF35: 5.7139706 | AG35: 9.1712769 | AH35: 12.193451 | AI35: 5.770193 | AJ35: 4.2105906 | AK35: 13.152593 | AL35: 10.382311 | AM35: 8.4358555 | AN35: 12.462547 | AO35: 15.571764 | AP35: 14.79925 | AQ35: 8.2846422 | AR35: 4.4328806 | AS35: 6.0962695 | AT35: 6.7941749 | AU35: 9.1066114 | AV35: 8.4299382 | AW35: 6.3188888 | AX35: 8.0462595 | AY35: 8.5700685 | AZ35: 2.1614464 | BA35: 5.9489376 | BB35: 3.9915291 | BC35: 5.2633257 | BD35: 3.9282983 | BE35: 8.589368 | BF35: 7.3296753 | BG35: 11.530017 | BH35: 10.888774 | BI35: 14.041011 | BJ35: 1.5331987 | BK35: 1.5712154 | BL35: -1.1751154 | BM35: 11.620425 | BN35: 12.539958 | BO35: 9.9386466 | BP35: 7.9933911 | BQ35: 1.5266819 | BR35: -14.335238 | BS35: -1.9629539 | BT35: 7.7456356 | BU35: -1.7216801 | BV35: 6.4858067 | BW35: 14.575581 | BX35: 5.9079247 | BY35: 2.7706545 | BZ35: 5.9863308 | CA35: 9.3734144 | CB35: -0.5076834 | CC35: 8.6300637 | CD35: 10.561066 | CE35: 19.567634 | CF35: -0.67507815 | CG35: 6.8530679 | CH35: 8.4050886
A36: Households and nonprofit organizations; net worth | B36: Currency | C36: 1000000 | D36: USD | E36: Z1/Z1/FL152090005.A | F36: FL152090005.A | G36: 806616 | H36: 885216 | I36: 984199 | J36: 1037019 | K36: 1079425 | L36: 1171443 | M36: 1280523 | N36: 1338242 | O36: 1386232 | P36: 1484120 | Q36: 1600734 | R36: 1710651 | S36: 1776003 | T36: 1921081 | U36: 2016085 | V36: 2091056 | W36: 2256719 | X36: 2319203 | Y36: 2422670 | Z36: 2604188 | AA36: 2803145 | AB36: 2902437 | AC36: 3204063 | AD36: 3595704 | AE36: 3660323 | AF36: 3875609 | AG36: 4294415 | AH36: 4889778 | AI36: 5101037 | AJ36: 5213063 | AK36: 5861925 | AL36: 6522666 | AM36: 7107581 | AN36: 7955603 | AO36: 9096396 | AP36: 10359452 | AQ36: 11258954 | AR36: 12084247 | AS36: 12980987 | AT36: 14097490 | AU36: 15549012 | AV36: 17180357 | AW36: 18436338 | AX36: 20181251 | AY36: 21976312 | AZ36: 22629587 | BA36: 24128374 | BB36: 25237606 | BC36: 26745508 | BD36: 27723515 | BE36: 30075730 | BF36: 32171612 | BG36: 35539480 | BH36: 39314914 | BI36: 43267374 | BJ36: 44488148 | BK36: 46021409 | BL36: 45935157 | BM36: 50913954 | BN36: 57782223 | BO36: 63340513 | BP36: 68263388 | BQ36: 69895699 | BR36: 61058258 | BS36: 61492801 | BT36: 65941998 | BU36: 67005103 | BV36: 72020139 | BW36: 80843597 | BX36: 86979596 | BY36: 89947002 | BZ36: 95192405 | CA36: 104026218 | CB36: 103933714 | CC36: 115663941 | CD36: 130673319 | CE36: 151701072 | CF36: 143858225 | CG36: 156064345 | CH36: 169427418
A37: Households and nonprofit organizations; net worth | B37: Currency | C37: 1000000 | D37: USD | E37: Z1/Z1/FC152090005.A | F37: FC152090005.A | H37: 78600 | I37: 98982 | J37: 52821 | K37: 42406 | L37: 92018 | M37: 109080 | N37: 57719 | O37: 47990 | P37: 97888 | Q37: 116614 | R37: 109918 | S37: 65352 | T37: 145078 | U37: 95004 | V37: 74971 | W37: 165663 | X37: 62484 | Y37: 103468 | Z37: 181518 | AA37: 198957 | AB37: 99293 | AC37: 301626 | AD37: 391641 | AE37: 64619 | AF37: 215286 | AG37: 418807 | AH37: 595363 | AI37: 211259 | AJ37: 112026 | AK37: 648862 | AL37: 660741 | AM37: 584915 | AN37: 848022 | AO37: 1140793 | AP37: 1263056 | AQ37: 899502 | AR37: 825293 | AS37: 896740 | AT37: 1116503 | AU37: 1451522 | AV37: 1631345 | AW37: 1255981 | AX37: 1744913 | AY37: 1795061 | AZ37: 653275 | BA37: 1498787 | BB37: 1109232 | BC37: 1507902 | BD37: 978007 | BE37: 2352214 | BF37: 2095882 | BG37: 3367868 | BH37: 3775435 | BI37: 3952460 | BJ37: 1220774 | BK37: 1533262 | BL37: -86252 | BM37: 4978796 | BN37: 6868269 | BO37: 5558289 | BP37: 4922876 | BQ37: 1632311 | BR37: -8837441 | BS37: 434543 | BT37: 4449198 | BU37: 1063105 | BV37: 5015036 | BW37: 8823458 | BX37: 6135999 | BY37: 2967406 | BZ37: 5245403 | CA37: 8833813 | CB37: -92505 | CC37: 11730228 | CD37: 15009378 | CE37: 21027753 | CF37: -7842847 | CG37: 12206120 | CH37: 13363073
A38: Households and nonprofit organizations; net worth | B38: Percent | C38: 1000000 | D38: USD | E38: Z1/Z1/PC152090005.A | F38: PC152090005.A | H38: 9.7444089 | I38: 11.181695 | J38: 5.3668792 | K38: 4.0892246 | L38: 8.5246882 | M38: 9.3116221 | N38: 4.5074459 | O38: 3.5860098 | P38: 7.0614741 | Q38: 7.8574229 | R38: 6.8667008 | S38: 3.8202757 | T38: 8.1687981 | U38: 4.94533 | V38: 3.7186529 | W38: 7.9224417 | X38: 2.7687987 | Y38: 4.461339 | Z38: 7.4924764 | AA38: 7.6398661 | AB38: 3.5421859 | AC38: 10.392159 | AD38: 12.223251 | AE38: 1.7971196 | AF38: 5.881601 | AG38: 10.806215 | AH38: 13.863645 | AI38: 4.3204172 | AJ38: 2.1961438 | AK38: 12.446854 | AL38: 11.271741 | AM38: 8.9674268 | AN38: 11.931226 | AO38: 14.339494 | AP38: 13.885239 | AQ38: 8.6829068 | AR38: 7.3301001 | AS38: 7.4207382 | AT38: 8.6010648 | AU38: 10.296315 | AV38: 10.491631 | AW38: 7.3105641 | AX38: 9.4645304 | AY38: 8.8946985 | AZ38: 2.972633 | BA38: 6.6231292 | BB38: 4.5972103 | BC38: 5.9748226 | BD38: 3.6567153 | BE38: 8.4845452 | BF38: 6.9686828 | BG38: 10.468446 | BH38: 10.623213 | BI38: 10.053334 | BJ38: 2.8214649 | BK38: 3.4464496 | BL38: -0.18741658 | BM38: 10.838749 | BN38: 13.489955 | BO38: 9.6193761 | BP38: 7.7720809 | BQ38: 2.391195 | BR38: -12.643756 | BS38: 0.7116858 | BT38: 7.2353148 | BU38: 1.6121815 | BV38: 7.4845584 | BW38: 12.251376 | BX38: 7.5899627 | BY38: 3.4116112 | BZ38: 5.8316601 | CA38: 9.2799558 | CB38: -0.088924262 | CC38: 11.286259 | CD38: 12.976713 | CE38: 16.091848 | CF38: -5.1699351 | CG38: 8.4848262 | CH38: 8.5625405

Sheet L4
A1: Download Page | F1: Z.1 Statistical Release for Jan 09, 2026
A2: Descriptions: | B2: Unit: | C2: Multiplier: | D2: Currency: | E2: Unique Identifier: | F2: Series Name: | G2: 1945 | H2: 1946 | I2: 1947 | J2: 1948 | K2: 1949 | L2: 1950 | M2: 1951 | N2: 1952 | O2: 1953 | P2: 1954 | Q2: 1955 | R2: 1956 | S2: 1957 | T2: 1958 | U2: 1959 | V2: 1960 | W2: 1961 | X2: 1962 | Y2: 1963 | Z2: 1964 | AA2: 1965 | AB2: 1966 | AC2: 1967 | AD2: 1968 | AE2: 1969 | AF2: 1970 | AG2: 1971 | AH2: 1972 | AI2: 1973 | AJ2: 1974 | AK2: 1975 | AL2: 1976 | AM2: 1977 | AN2: 1978 | AO2: 1979 | AP2: 1980 | AQ2: 1981 | AR2: 1982 | AS2: 1983 | AT2: 1984 | AU2: 1985 | AV2: 1986 | AW2: 1987 | AX2: 1988 | AY2: 1989 | AZ2: 1990 | BA2: 1991 | BB2: 1992 | BC2: 1993 | BD2: 1994 | BE2: 1995 | BF2: 1996 | BG2: 1997 | BH2: 1998 | BI2: 1999 | BJ2: 2000 | BK2: 2001 | BL2: 2002 | BM2: 2003 | BN2: 2004 | BO2: 2005 | BP2: 2006 | BQ2: 2007 | BR2: 2008 | BS2: 2009 | BT2: 2010 | BU2: 2011 | BV2: 2012 | BW2: 2013 | BX2: 2014 | BY2: 2015 | BZ2: 2016 | CA2: 2017 | CB2: 2018 | CC2: 2019 | CD2: 2020 | CE2: 2021 | CF2: 2022 | CG2: 2023 | CH2: 2024
A3: All domestic sectors; gross fixed investment, current cost basis | B3: Currency | C3: 1000000 | D3: USD | E3: Z1/Z1/FL885019865.A | F3: FL885019865.A | G3: 554840 | H3: 639557 | I3: 734155 | J3: 779995 | K3: 785039 | L3: 871996 | M3: 957305 | N3: 1012970 | O3: 1051269 | P3: 1099956 | Q3: 1197093 | R3: 1301496 | S3: 1369440 | T3: 1415027 | U3: 1471124 | V3: 1520449 | W3: 1580092 | X3: 1652675 | Y3: 1717352 | Z3: 1829486 | AA3: 1954131 | AB3: 2119630 | AC3: 2285122 | AD3: 2511156 | AE3: 2743748 | AF3: 2990474 | AG3: 3294294 | AH3: 3621510 | AI3: 4110445 | AJ3: 4887525 | AK3: 5276582 | AL3: 5747011 | AM3: 6415098 | AN3: 7259791 | AO3: 8359565 | AP3: 9511476 | AQ3: 10489750 | AR3: 11083259 | AS3: 11467860 | AT3: 12138928 | AU3: 12757908 | AV3: 13547111 | AW3: 14341072 | AX3: 15226770 | AY3: 16092388 | AZ3: 16854534 | BA3: 17271370 | BB3: 17998077 | BC3: 18899579 | BD3: 20025720 | BE3: 20998211 | BF3: 21999462 | BG3: 23167721 | BH3: 24470593 | BI3: 26040669 | BJ3: 27757018 | BK3: 29308485 | BL3: 30735473 | BM3: 32394949 | BN3: 35710996 | BO3: 39290344 | BP3: 42505719 | BQ3: 44406957 | BR3: 45918921 | BS3: 45079011 | BT3: 45978958 | BU3: 47571642 | BV3: 49070496 | BW3: 51481571 | BX3: 53583348 | BY3: 54904898 | BZ3: 57232242 | CA3: 59662646 | CB3: 62780152 | CC3: 65316427 | CD3: 68156365 | CE3: 77384510 | CF3: 86358882 | CG3: 88606168 | CH3: 91548536
A4: All domestic sectors; gross fixed investment, structures, current cost basis | B4: Currency | C4: 1000000 | D4: USD | E4: Z1/Z1/FL885019665.A | F4: FL885019665.A | G4: 419286 | H4: 500717 | I4: 591591 | J4: 630942 | K4: 638466 | L4: 712794 | M4: 781948 | N4: 823187 | O4: 842237 | P4: 877884 | Q4: 952845 | R4: 1030647 | S4: 1076324 | T4: 1110097 | U4: 1147648 | V4: 1182474 | W4: 1228684 | X4: 1280576 | Y4: 1326105 | Z4: 1414608 | AA4: 1510035 | AB4: 1632462 | AC4: 1752389 | AD4: 1928902 | AE4: 2106358 | AF4: 2295588 | AG4: 2558114 | AH4: 2833280 | AI4: 3238581 | AJ4: 3853875 | AK4: 4115062 | AL4: 4469960 | AM4: 4994166 | AN4: 5653512 | AO4: 6527060 | AP4: 7410543 | AQ4: 8141430 | AR4: 8560882 | AS4: 8810123 | AT4: 9274517 | AU4: 9739326 | AV4: 10352404 | AW4: 10963233 | AX4: 11614122 | AY4: 12248721 | AZ4: 12774773 | BA4: 13037333 | BB4: 13610492 | BC4: 14332017 | BD4: 15215953 | BE4: 15931972 | BF4: 16726793 | BG4: 17674932 | BH4: 18714826 | BI4: 19922932 | BJ4: 21266407 | BK4: 22640384 | BL4: 23935312 | BM4: 25419933 | BN4: 28377666 | BO4: 31586635 | BP4: 34322145 | BQ4: 35785649 | BR4: 36854807 | BS4: 35982272 | BT4: 36597055 | BU4: 37775222 | BV4: 38895067 | BW4: 40905869 | BX4: 42600653 | BY4: 43636925 | BZ4: 45572307 | CA4: 47468929 | CB4: 49966039 | CC4: 51988666 | CD4: 54235283 | CE4: 62396934 | CF4: 70186705 | CG4: 71592596 | CH4: 73687068
A5: All domestic sectors; gross fixed investment, equipment, current cost basis | B5: Currency | C5: 1000000 | D5: USD | E5: Z1/Z1/FL885019265.A | F5: FL885019265.A | G5: 123201 | H5: 124673 | I5: 126427 | J5: 131562 | K5: 128154 | L5: 138649 | M5: 152960 | N5: 165512 | O5: 182254 | P5: 192749 | Q5: 211346 | R5: 232880 | S5: 249722 | T5: 256476 | U5: 269549 | V5: 278747 | W5: 286183 | X5: 300896 | Y5: 311742 | Z5: 326652 | AA5: 346059 | AB5: 377580 | AC5: 409830 | AD5: 444342 | AE5: 482034 | AF5: 522686 | AG5: 551018 | AH5: 588714 | AI5: 649650 | AJ5: 782835 | AK5: 890403 | AL5: 983282 | AM5: 1101024 | AN5: 1252534 | AO5: 1432317 | AP5: 1646139 | AQ5: 1833217 | AR5: 1954497 | AS5: 2036340 | AT5: 2184837 | AU5: 2281134 | AV5: 2402655 | AW5: 2512802 | AX5: 2672774 | AY5: 2829172 | AZ5: 2989287 | BA5: 3072810 | BB5: 3161902 | BC5: 3284486 | BD5: 3453797 | BE5: 3636012 | BF5: 3774128 | BG5: 3900520 | BH5: 4060519 | BI5: 4276780 | BJ5: 4499225 | BK5: 4604355 | BL5: 4667015 | BM5: 4727182 | BN5: 4980135 | BO5: 5204911 | BP5: 5547022 | BQ5: 5806818 | BR5: 6108187 | BS5: 6055930 | BT5: 6197481 | BU5: 6467262 | BV5: 6718880 | BW5: 6938128 | BX5: 7202300 | BY5: 7389895 | BZ5: 7576968 | CA5: 7842334 | CB5: 8202312 | CC5: 8462825 | CD5: 8637503 | CE5: 9309444 | CF5: 9974341 | CG5: 10371215 | CH5: 10729364
A6: All domestic sectors; nonresidential intellectual property products, current cost basis | B6: Currency | C6: 1000000 | D6: USD | E6: Z1/Z1/FL885013765.A | F6: FL885013765.A | G6: 12353 | H6: 14167 | I6: 16137 | J6: 17491 | K6: 18419 | L6: 20553 | M6: 22397 | N6: 24271 | O6: 26778 | P6: 29323 | Q6: 32902 | R6: 37969 | S6: 43394 | T6: 48454 | U6: 53927 | V6: 59228 | W6: 65225 | X6: 71203 | Y6: 79505 | Z6: 88226 | AA6: 98037 | AB6: 109588 | AC6: 122903 | AD6: 137912 | AE6: 155356 | AF6: 172200 | AG6: 185162 | AH6: 199516 | AI6: 222214 | AJ6: 250815 | AK6: 271117 | AL6: 293769 | AM6: 319908 | AN6: 353745 | AO6: 400188 | AP6: 454794 | AQ6: 515103 | AR6: 567880 | AS6: 621397 | AT6: 679574 | AU6: 737448 | AV6: 792052 | AW6: 865037 | AX6: 939874 | AY6: 1014495 | AZ6: 1090474 | BA6: 1161227 | BB6: 1225683 | BC6: 1283076 | BD6: 1355970 | BE6: 1430227 | BF6: 1498541 | BG6: 1592269 | BH6: 1695248 | BI6: 1840957 | BJ6: 1991386 | BK6: 2063746 | BL6: 2133146 | BM6: 2247834 | BN6: 2353195 | BO6: 2498798 | BP6: 2636552 | BQ6: 2814490 | BR6: 2955927 | BS6: 3040809 | BT6: 3184422 | BU6: 3329158 | BV6: 3456549 | BW6: 3637574 | BX6: 3780395 | BY6: 3878078 | BZ6: 4082967 | CA6: 4351383 | CB6: 4611801 | CC6: 4864936 | CD6: 5283579 | CE6: 5678132 | CF6: 6197836 | CG6: 6642357 | CH6: 7132104
A7: All domestic sectors; nonresidential software, current cost basis | B7: Currency | C7: 1000000 | D7: USD | E7: Z1/Z1/FL885013365.A | F7: FL885013365.A | G7: 0 | H7: 0 | I7: 0 | J7: 0 | K7: 0 | L7: 0 | M7: 0 | N7: 0 | O7: 0 | P7: 0 | Q7: 0 | R7: 0 | S7: 0 | T7: 0 | U7: 13 | V7: 143 | W7: 276 | X7: 413 | Y7: 730 | Z7: 1057 | AA7: 1387 | AB7: 1973 | AC7: 2570 | AD7: 3176 | AE7: 4152 | AF7: 5362 | AG7: 6209 | AH7: 7288 | AI7: 8704 | AJ7: 10902 | AK7: 12923 | AL7: 14800 | AM7: 16206 | AN7: 18448 | AO7: 22522 | AP7: 27304 | AQ7: 33168 | AR7: 38683 | AS7: 44262 | AT7: 52415 | AU7: 60560 | AV7: 68323 | AW7: 77871 | AX7: 88016 | AY7: 100832 | AZ7: 116864 | BA7: 125564 | BB7: 134848 | BC7: 147349 | BD7: 156556 | BE7: 167936 | BF7: 178273 | BG7: 200364 | BH7: 230700 | BI7: 276063 | BJ7: 323314 | BK7: 344516 | BL7: 347925 | BM7: 348727 | BN7: 364112 | BO7: 387190 | BP7: 413355 | BQ7: 443973 | BR7: 481308 | BS7: 493420 | BT7: 510703 | BU7: 546240 | BV7: 582208 | BW7: 621812 | BX7: 660054 | BY7: 694015 | BZ7: 741107 | CA7: 801189 | CB7: 869362 | CC7: 926420 | CD7: 984547 | CE7: 1067325 | CF7: 1197965 | CG7: 1298439 | CH7: 1433440
A8: All domestic sectors; nonresidential research and development, current cost basis | B8: Currency | C8: 1000000 | D8: USD | E8: Z1/Z1/FL885013465.A | F8: FL885013465.A | G8: 7056 | H8: 8274 | I8: 9381 | J8: 10389 | K8: 11080 | L8: 12686 | M8: 14289 | N8: 15854 | O8: 17805 | P8: 19864 | Q8: 22754 | R8: 27073 | S8: 31597 | T8: 36087 | U8: 40444 | V8: 44975 | W8: 49808 | X8: 54970 | Y8: 61797 | Z8: 69064 | AA8: 76848 | AB8: 86091 | AC8: 96393 | AD8: 108592 | AE8: 122543 | AF8: 136142 | AG8: 147435 | AH8: 159403 | AI8: 179540 | AJ8: 203107 | AK8: 219124 | AL8: 236710 | AM8: 257438 | AN8: 284296 | AO8: 321328 | AP8: 366160 | AQ8: 414134 | AR8: 455024 | AS8: 495864 | AT8: 536363 | AU8: 577850 | AV8: 615324 | AW8: 668065 | AX8: 723747 | AY8: 772926 | AZ8: 820163 | BA8: 871585 | BB8: 918347 | BC8: 953141 | BD8: 1004564 | BE8: 1051183 | BF8: 1093464 | BG8: 1150860 | BH8: 1212522 | BI8: 1291727 | BJ8: 1375426 | BK8: 1416155 | BL8: 1466436 | BM8: 1563265 | BN8: 1638260 | BO8: 1741960 | BP8: 1829618 | BQ8: 1965451 | BR8: 2059773 | BS8: 2131212 | BT8: 2248550 | BU8: 2352420 | BV8: 2431766 | BW8: 2566447 | BX8: 2659473 | BY8: 2704569 | BZ8: 2846151 | CA8: 3034315 | CB8: 3210017 | CC8: 3385581 | CD8: 3733117 | CE8: 4012474 | CF8: 4354341 | CG8: 4654251 | CH8: 4986446
